<?xml version="1.0" ?>
<robot name="simple_evolved_corner_v2">
	<link name="torso">
		<inertial>
			<origin xyz="0.0 0.0 0.0" rpy="0.0 0.0 0.0"/>
			<mass value="1.0"/>
			<inertia ixx="0.0002" ixy="0.0" ixz="0.0" iyy="0.0002" iyz="0.0" izz="0.0001"/>
		</inertial>
		<visual>
			<origin xyz="0.0 0.0 0.0" rpy="0.0 1.5708 0.0"/>
			<geometry>
				<cylinder radius="0.04" length="0.2"/>
			</geometry>
			<material name="green">
				<color rgba="0.2 0.8 0.2 1.0"/>
			</material>
		</visual>
		<collision>
			<origin xyz="0.0 0.0 0.0" rpy="0.0 1.5708 0.0"/>
			<geometry>
				<cylinder radius="0.04" length="0.2"/>
			</geometry>
		</collision>
	</link>
	<link name="link_f91e56d2-5093-480a-b536-37c47da06095_limb">
		<visual>
			<origin xyz="-0.024 0.012 -0.035" rpy="0.0 0.0 0.0"/>
			<geometry>
				<cylinder radius="0.013333333333333334" length="0.08"/>
			</geometry>
			<material name="red">
				<color rgba="1.0 0.0 0.0 0.9"/>
			</material>
		</visual>
		<collision>
			<origin xyz="-0.024 0.012 -0.035" rpy="0.0 0.0 0.0"/>
			<geometry>
				<cylinder radius="0.013333333333333334" length="0.08"/>
			</geometry>
		</collision>
	</link>
	<link name="link_intermediate_633efa02-0838-4db9-906a-c1e85e5a7b09_limb"/>
	<link name="link_437d3f0f-c77d-48f3-bbdd-cb9e4e8b6220_limb">
		<visual>
			<origin xyz="0 0 -0.035" rpy="0 0 0"/>
			<geometry>
				<cylinder radius="0.013333333333333334" length="0.08"/>
			</geometry>
			<material name="red">
				<color rgba="1.0 0 0 0.9"/>
			</material>
		</visual>
		<collision>
			<origin xyz="0 0 -0.035" rpy="0 0 0"/>
			<geometry>
				<cylinder radius="0.013333333333333334" length="0.08"/>
			</geometry>
		</collision>
	</link>
	<link name="link_intermediate_228df19b-cfdf-429f-96a9-eebf8f32254b_limb"/>
	<joint name="joint_torso_to_link_intermediate_633efa02-0838-4db9-906a-c1e85e5a7b09_limb" type="revolute">
		<origin xyz="-0.024 0.012 -0.035" rpy="0.0 0.0 0.0"/>
		<parent link="torso"/>
		<child link="link_intermediate_633efa02-0838-4db9-906a-c1e85e5a7b09_limb"/>
		<axis xyz="0.0 0.0 1.0"/>
		<limit effort="1.0" velocity="2.0" lower="-1.5" upper="1.5"/>
	</joint>
	<joint name="joint_link_intermediate_633efa02-0838-4db9-906a-c1e85e5a7b09_limb_to_link_f91e56d2-5093-480a-b536-37c47da06095_limb" type="revolute">
		<origin xyz="0.0 0.0 0.0" rpy="0.0 0.0 0.0"/>
		<parent link="link_intermediate_633efa02-0838-4db9-906a-c1e85e5a7b09_limb"/>
		<child link="link_f91e56d2-5093-480a-b536-37c47da06095_limb"/>
		<axis xyz="0.0 1.0 0.0"/>
		<limit effort="1.0" velocity="2.0" lower="-1.5" upper="1.5"/>
	</joint>
	<joint name="joint_torso_to_link_intermediate_228df19b-cfdf-429f-96a9-eebf8f32254b_limb" type="revolute">
		<origin xyz="0 0 -0.035" rpy="0 0 0"/>
		<parent link="torso"/>
		<child link="link_intermediate_228df19b-cfdf-429f-96a9-eebf8f32254b_limb"/>
		<axis xyz="0 0 1"/>
		<limit effort="1.0" velocity="2.0" lower="-1.5" upper="1.5"/>
	</joint>
	<joint name="joint_link_intermediate_228df19b-cfdf-429f-96a9-eebf8f32254b_limb_to_link_437d3f0f-c77d-48f3-bbdd-cb9e4e8b6220_limb" type="revolute">
		<origin xyz="0 0 0" rpy="0 0 0"/>
		<parent link="link_intermediate_228df19b-cfdf-429f-96a9-eebf8f32254b_limb"/>
		<child link="link_437d3f0f-c77d-48f3-bbdd-cb9e4e8b6220_limb"/>
		<axis xyz="0 1 0"/>
		<limit effort="1.0" velocity="2.0" lower="-1.5" upper="1.5"/>
	</joint>
</robot>
