<?xml version="1.0" ?>
<robot name="evolved_v2_leg_2">
	<link name="torso">
		<inertial>
			<origin xyz="0.0 0.0 0.0" rpy="0.0 0.0 0.0"/>
			<mass value="1.0"/>
			<inertia ixx="0.0002" ixy="0.0" ixz="0.0" iyy="0.0002" iyz="0.0" izz="0.0001"/>
		</inertial>
		<visual>
			<origin xyz="0.0 0.0 0.0" rpy="0.0 1.5708 0.0"/>
			<geometry>
				<cylinder radius="0.04" length="0.2"/>
			</geometry>
			<material name="green">
				<color rgba="0.2 0.8 0.2 1.0"/>
			</material>
		</visual>
		<collision>
			<origin xyz="0.0 0.0 0.0" rpy="0.0 1.5708 0.0"/>
			<geometry>
				<cylinder radius="0.04" length="0.2"/>
			</geometry>
		</collision>
	</link>
	<link name="link_ca74ad48-c794-4a52-95b7-17964e95c88f_limb">
		<visual>
			<origin xyz="-0.024 -0.012 -0.035" rpy="0 0 0"/>
			<geometry>
				<cylinder radius="0.013333333333333334" length="0.08"/>
			</geometry>
			<material name="red">
				<color rgba="1.0 0 0 0.9"/>
			</material>
		</visual>
		<collision>
			<origin xyz="-0.024 -0.012 -0.035" rpy="0 0 0"/>
			<geometry>
				<cylinder radius="0.013333333333333334" length="0.08"/>
			</geometry>
		</collision>
	</link>
	<link name="link_intermediate_7f7dbe97-09e0-4cfa-8e3f-e4ba3963c471_limb"/>
	<joint name="joint_torso_to_link_intermediate_7f7dbe97-09e0-4cfa-8e3f-e4ba3963c471_limb" type="revolute">
		<origin xyz="-0.024 -0.012 -0.035" rpy="0 0 0"/>
		<parent link="torso"/>
		<child link="link_intermediate_7f7dbe97-09e0-4cfa-8e3f-e4ba3963c471_limb"/>
		<axis xyz="0 0 1"/>
		<limit effort="1.0" velocity="2.0" lower="-1.5" upper="1.5"/>
	</joint>
	<joint name="joint_link_intermediate_7f7dbe97-09e0-4cfa-8e3f-e4ba3963c471_limb_to_link_ca74ad48-c794-4a52-95b7-17964e95c88f_limb" type="revolute">
		<origin xyz="0 0 0" rpy="0 0 0"/>
		<parent link="link_intermediate_7f7dbe97-09e0-4cfa-8e3f-e4ba3963c471_limb"/>
		<child link="link_ca74ad48-c794-4a52-95b7-17964e95c88f_limb"/>
		<axis xyz="0 1 0"/>
		<limit effort="1.0" velocity="2.0" lower="-1.5" upper="1.5"/>
	</joint>
</robot>
