<?xml version="1.0"?>
<robot name="hexapod">
  <link name="torso">
    <visual><geometry><cylinder radius="0.03" length="0.2"/></geometry></visual>
    <collision><geometry><cylinder radius="0.03" length="0.2"/></geometry></collision>
  </link>

  <link name="inter_0">
  </link>
  <link name="leg_0">
    <visual><origin xyz="0 0 -0.1" rpy="0 0 0"/>
      <geometry><cylinder radius="0.01" length="0.2"/></geometry>
    </visual>
    <collision><origin xyz="0 0 -0.1" rpy="0 0 0"/>
      <geometry><cylinder radius="0.01" length="0.2"/></geometry>
    </collision>
  </link>
  <!-- ===== Joint 0 Part A (Pitch) ===== -->
  <joint name="joint_0_pitch" type="revolute">
    <parent link="torso"/>
    <child link="inter_0"/>
    <origin xyz="0.100 0.040 0" rpy="0 0 0"/>
    <axis xyz="0 0 1"/>
    <limit lower="-1.57" upper="1.57" effort="1.0" velocity="2.0"/>
  </joint>

  <!-- ===== Joint 0 Part B (Yaw) ===== -->
  <joint name="joint_0_yaw" type="revolute">
    <parent link="inter_0"/>
    <child link="leg_0"/>
    <origin xyz="0 0 0" rpy="0 0 0"/>
    <axis xyz="0 1 0"/>
    <limit lower="-1.57" upper="1.57" effort="1.0" velocity="2.0"/>
  </joint>
  <link name="inter_1">

  </link>
  <link name="leg_1">

    <visual><origin xyz="0 0 -0.1" rpy="0 0 0"/>
      <geometry><cylinder radius="0.01" length="0.2"/></geometry>
    </visual>
    <collision><origin xyz="0 0 -0.1" rpy="0 0 0"/>
      <geometry><cylinder radius="0.01" length="0.2"/></geometry>
    </collision>
  </link>
  <!-- ===== Joint 1 Part A (Pitch) ===== -->
  <joint name="joint_1_pitch" type="revolute">
    <parent link="torso"/>
    <child link="inter_1"/>
    <origin xyz="0.100 -0.040 0" rpy="0 0 0"/>
    <axis xyz="0 0 1"/>
    <limit lower="-1.57" upper="1.57" effort="1.0" velocity="2.0"/>
  </joint>

  <!-- ===== Joint 1 Part B (Yaw) ===== -->
  <joint name="joint_1_yaw" type="revolute">
    <parent link="inter_1"/>
    <child link="leg_1"/>
    <origin xyz="0 0 0" rpy="0 0 0"/>
    <axis xyz="0 1 0"/>
    <limit lower="-1.57" upper="1.57" effort="1.0" velocity="2.0"/>
  </joint>
  <link name="inter_2">
 
  </link>
  <link name="leg_2">

    <visual><origin xyz="0 0 -0.1" rpy="0 0 0"/>
      <geometry><cylinder radius="0.01" length="0.2"/></geometry>
    </visual>
    <collision><origin xyz="0 0 -0.1" rpy="0 0 0"/>
      <geometry><cylinder radius="0.01" length="0.2"/></geometry>
    </collision>
  </link>
  <!-- ===== Joint 2 Part A (Pitch) ===== -->
  <joint name="joint_2_pitch" type="revolute">
    <parent link="torso"/>
    <child link="inter_2"/>
    <origin xyz="0.000 0.040 0" rpy="0 0 0"/>
    <axis xyz="0 0 1"/>
    <limit lower="-1.57" upper="1.57" effort="1.0" velocity="2.0"/>
  </joint>

  <!-- ===== Joint 2 Part B (Yaw) ===== -->
  <joint name="joint_2_yaw" type="revolute">
    <parent link="inter_2"/>
    <child link="leg_2"/>
    <origin xyz="0 0 0" rpy="0 0 0"/>
    <axis xyz="0 1 0"/>
    <limit lower="-1.57" upper="1.57" effort="1.0" velocity="2.0"/>
  </joint>
  <link name="inter_3">

  </link>
  <link name="leg_3">

    <visual><origin xyz="0 0 -0.1" rpy="0 0 0"/>
      <geometry><cylinder radius="0.01" length="0.2"/></geometry>
    </visual>
    <collision><origin xyz="0 0 -0.1" rpy="0 0 0"/>
      <geometry><cylinder radius="0.01" length="0.2"/></geometry>
    </collision>
  </link>
  <!-- ===== Joint 3 Part A (Pitch) ===== -->
  <joint name="joint_3_pitch" type="revolute">
    <parent link="torso"/>
    <child link="inter_3"/>
    <origin xyz="0.000 -0.040 0" rpy="0 0 0"/>
    <axis xyz="0 0 1"/>
    <limit lower="-1.57" upper="1.57" effort="1.0" velocity="2.0"/>
  </joint>

  <!-- ===== Joint 3 Part B (Yaw) ===== -->
  <joint name="joint_3_yaw" type="revolute">
    <parent link="inter_3"/>
    <child link="leg_3"/>
    <origin xyz="0 0 0" rpy="0 0 0"/>
    <axis xyz="0 1 0"/>
    <limit lower="-1.57" upper="1.57" effort="1.0" velocity="2.0"/>
  </joint>
  <link name="inter_4">

  </link>
  <link name="leg_4">

    <visual><origin xyz="0 0 -0.1" rpy="0 0 0"/>
      <geometry><cylinder radius="0.01" length="0.2"/></geometry>
    </visual>
    <collision><origin xyz="0 0 -0.1" rpy="0 0 0"/>
      <geometry><cylinder radius="0.01" length="0.2"/></geometry>
    </collision>
  </link>
  <!-- ===== Joint 4 Part A (Pitch) ===== -->
  <joint name="joint_4_pitch" type="revolute">
    <parent link="torso"/>
    <child link="inter_4"/>
    <origin xyz="-0.100 0.040 0" rpy="0 0 0"/>
    <axis xyz="0 0 1"/>
    <limit lower="-1.57" upper="1.57" effort="1.0" velocity="2.0"/>
  </joint>

  <!-- ===== Joint 4 Part B (Yaw) ===== -->
  <joint name="joint_4_yaw" type="revolute">
    <parent link="inter_4"/>
    <child link="leg_4"/>
    <origin xyz="0 0 0" rpy="0 0 0"/>
    <axis xyz="0 1 0"/>
    <limit lower="-1.57" upper="1.57" effort="1.0" velocity="2.0"/>
  </joint>
  <link name="inter_5">

  </link>
  <link name="leg_5">

    <visual><origin xyz="0 0 -0.1" rpy="0 0 0"/>
      <geometry><cylinder radius="0.01" length="0.2"/></geometry>
    </visual>
    <collision><origin xyz="0 0 -0.1" rpy="0 0 0"/>
      <geometry><cylinder radius="0.01" length="0.2"/></geometry>
    </collision>
  </link>
  <!-- ===== Joint 5 Part A (Pitch) ===== -->
  <joint name="joint_5_pitch" type="revolute">
    <parent link="torso"/>
    <child link="inter_5"/>
    <origin xyz="-0.100 -0.040 0" rpy="0 0 0"/>
    <axis xyz="0 0 1"/>
    <limit lower="-1.57" upper="1.57" effort="1.0" velocity="2.0"/>
  </joint>

  <!-- ===== Joint 5 Part B (Yaw) ===== -->
  <joint name="joint_5_yaw" type="revolute">
    <parent link="inter_5"/>
    <child link="leg_5"/>
    <origin xyz="0 0 0" rpy="0 0 0"/>
    <axis xyz="0 1 0"/>
    <limit lower="-1.57" upper="1.57" effort="1.0" velocity="2.0"/>
  </joint>
</robot>