<?xml version="1.0" ?>
<robot name="simple_evolved_3">
	<link name="torso">
		<inertial>
			<origin xyz="0.0 0.0 0.0" rpy="0.0 0.0 0.0"/>
			<mass value="1.0"/>
			<inertia ixx="0.0002" ixy="0.0" ixz="0.0" iyy="0.0002" iyz="0.0" izz="0.0001"/>
		</inertial>
		<visual>
			<origin xyz="0.0 0.0 0.0" rpy="0.0 1.5708 0.0"/>
			<geometry>
				<cylinder radius="0.04" length="0.2"/>
			</geometry>
			<material name="green">
				<color rgba="0.2 0.8 0.2 1.0"/>
			</material>
		</visual>
		<collision>
			<origin xyz="0.0 0.0 0.0" rpy="0.0 1.5708 0.0"/>
			<geometry>
				<cylinder radius="0.04" length="0.2"/>
			</geometry>
		</collision>
	</link>
	<link name="link_ff354514-30d3-4fb5-9f52-8d78e1118d53_limb">
		<inertial>
			<origin xyz="0.0 0.0 0.0" rpy="0.0 0.0 0.0"/>
			<mass value="0.1"/>
			<inertia ixx="0.0002" ixy="0.0" ixz="0.0" iyy="0.0002" iyz="0.0" izz="0.0001"/>
		</inertial>
		<visual>
			<origin xyz="0.01 0.0 -0.04" rpy="0.0 0.0 0.0"/>
			<geometry>
				<cylinder radius="0.01" length="0.1"/>
			</geometry>
			<material name="red">
				<color rgba="1.0 0.0 0.0 0.9"/>
			</material>
		</visual>
		<collision>
			<origin xyz="0.01 0.0 -0.04" rpy="0.0 0.0 0.0"/>
			<geometry>
				<cylinder radius="0.01" length="0.1"/>
			</geometry>
		</collision>
	</link>
	<link name="link_intermediate_b21211a4-4044-415b-a2d6-26081f579b01_limb">
		<inertial>
			<origin xyz="0.0 0.0 0.0" rpy="0.0 0.0 0.0"/>
			<mass value="0.001"/>
			<inertia ixx="1e-06" ixy="0.0" ixz="0.0" iyy="1e-06" iyz="0.0" izz="1e-06"/>
		</inertial>
	</link>
	<link name="link_aa350b03-589d-45c7-b31f-8d923d017d76_limb">
		<inertial>
			<origin xyz="0.0 0.0 0.0" rpy="0.0 0.0 0.0"/>
			<mass value="0.1"/>
			<inertia ixx="0.0002" ixy="0.0" ixz="0.0" iyy="0.0002" iyz="0.0" izz="0.0001"/>
		</inertial>
		<visual>
			<origin xyz="0.03 0.0 -0.04" rpy="0.0 0.0 0.0"/>
			<geometry>
				<cylinder radius="0.01" length="0.1"/>
			</geometry>
			<material name="red">
				<color rgba="1.0 0.0 0.0 0.9"/>
			</material>
		</visual>
		<collision>
			<origin xyz="0.03 0.0 -0.04" rpy="0.0 0.0 0.0"/>
			<geometry>
				<cylinder radius="0.01" length="0.1"/>
			</geometry>
		</collision>
	</link>
	<link name="link_intermediate_de175960-ce65-42ce-ae50-3e79acf95f2c_limb">
		<inertial>
			<origin xyz="0.0 0.0 0.0" rpy="0.0 0.0 0.0"/>
			<mass value="0.001"/>
			<inertia ixx="1e-06" ixy="0.0" ixz="0.0" iyy="1e-06" iyz="0.0" izz="1e-06"/>
		</inertial>
	</link>
	<link name="link_4bbe0ed3-e8a1-4eac-aa82-612e1654bdb4_limb">
		<inertial>
			<origin xyz="0 0 0" rpy="0 0 0"/>
			<mass value="0.1"/>
			<inertia ixx="0.0002" ixy="0" ixz="0" iyy="0.0002" iyz="0" izz="0.0001"/>
		</inertial>
		<visual>
			<origin xyz="0.02 0.0 -0.04" rpy="0 0 0"/>
			<geometry>
				<cylinder radius="0.01" length="0.1"/>
			</geometry>
			<material name="red">
				<color rgba="1.0 0 0 0.9"/>
			</material>
		</visual>
		<collision>
			<origin xyz="0.02 0.0 -0.04" rpy="0 0 0"/>
			<geometry>
				<cylinder radius="0.01" length="0.1"/>
			</geometry>
		</collision>
	</link>
	<link name="link_intermediate_a019b6b1-effc-4914-9035-788da89f9254_limb">
		<inertial>
			<origin xyz="0 0 0" rpy="0 0 0"/>
			<mass value="0.001"/>
			<inertia ixx="1e-06" ixy="0" ixz="0" iyy="1e-06" iyz="0" izz="1e-06"/>
		</inertial>
	</link>
	<joint name="joint_torso_to_link_intermediate_b21211a4-4044-415b-a2d6-26081f579b01_limb" type="revolute">
		<origin xyz="0.01 0.0 -0.04" rpy="0.0 0.0 0.0"/>
		<parent link="torso"/>
		<child link="link_intermediate_b21211a4-4044-415b-a2d6-26081f579b01_limb"/>
		<axis xyz="0.0 0.0 1.0"/>
		<limit effort="1.0" velocity="2.0" lower="-1.5" upper="1.5"/>
	</joint>
	<joint name="joint_link_intermediate_b21211a4-4044-415b-a2d6-26081f579b01_limb_to_link_ff354514-30d3-4fb5-9f52-8d78e1118d53_limb" type="revolute">
		<origin xyz="0.0 0.0 0.0" rpy="0.0 0.0 0.0"/>
		<parent link="link_intermediate_b21211a4-4044-415b-a2d6-26081f579b01_limb"/>
		<child link="link_ff354514-30d3-4fb5-9f52-8d78e1118d53_limb"/>
		<axis xyz="0.0 1.0 0.0"/>
		<limit effort="1.0" velocity="2.0" lower="-1.5" upper="1.5"/>
	</joint>
	<joint name="joint_torso_to_link_intermediate_de175960-ce65-42ce-ae50-3e79acf95f2c_limb" type="revolute">
		<origin xyz="0.03 0.0 -0.04" rpy="0.0 0.0 0.0"/>
		<parent link="torso"/>
		<child link="link_intermediate_de175960-ce65-42ce-ae50-3e79acf95f2c_limb"/>
		<axis xyz="0.0 0.0 1.0"/>
		<limit effort="1.0" velocity="2.0" lower="-1.5" upper="1.5"/>
	</joint>
	<joint name="joint_link_intermediate_de175960-ce65-42ce-ae50-3e79acf95f2c_limb_to_link_aa350b03-589d-45c7-b31f-8d923d017d76_limb" type="revolute">
		<origin xyz="0.0 0.0 0.0" rpy="0.0 0.0 0.0"/>
		<parent link="link_intermediate_de175960-ce65-42ce-ae50-3e79acf95f2c_limb"/>
		<child link="link_aa350b03-589d-45c7-b31f-8d923d017d76_limb"/>
		<axis xyz="0.0 1.0 0.0"/>
		<limit effort="1.0" velocity="2.0" lower="-1.5" upper="1.5"/>
	</joint>
	<joint name="joint_torso_to_link_intermediate_a019b6b1-effc-4914-9035-788da89f9254_limb" type="revolute">
		<origin xyz="0.02 0.0 -0.04" rpy="0 0 0"/>
		<parent link="torso"/>
		<child link="link_intermediate_a019b6b1-effc-4914-9035-788da89f9254_limb"/>
		<axis xyz="0 0 1"/>
		<limit effort="1.0" velocity="2.0" lower="-1.5" upper="1.5"/>
	</joint>
	<joint name="joint_link_intermediate_a019b6b1-effc-4914-9035-788da89f9254_limb_to_link_4bbe0ed3-e8a1-4eac-aa82-612e1654bdb4_limb" type="revolute">
		<origin xyz="0 0 0" rpy="0 0 0"/>
		<parent link="link_intermediate_a019b6b1-effc-4914-9035-788da89f9254_limb"/>
		<child link="link_4bbe0ed3-e8a1-4eac-aa82-612e1654bdb4_limb"/>
		<axis xyz="0 1 0"/>
		<limit effort="1.0" velocity="2.0" lower="-1.5" upper="1.5"/>
	</joint>
</robot>
